<?xml version="1.0"?>
<robot name="R2D2" xmlns:xacro="http://ros.org/wiki/xacro">
<material name="blue">
  <color rgba="0 0 0.8 1"/>
</material>

<material name="black">
  <color rgba="0 0 0 1"/>
</material>

<material name="white">
  <color rgba="1 1 1 1"/>
</material>
<xacro:property name="up_z" value="0.5" />
  <xacro:macro name="default_inertial" params="mass">
    <inertial>
      <mass value="${mass}" />
      <inertia ixx="1.0" ixy="0.0" ixz="0.0" iyy="1.0" iyz="0.0" izz="1.0" />
    </inertial>
  </xacro:macro>

<!--link name="base_footprint">
</link-->
  
<link name="base_link">
    <visual>
      <geometry>
         <box size="2 0.8 0.05"/>
      </geometry>
     <origin xyz="0 0 ${up_z}" rpy="0 0 0"/>
     <material name="blue"/>
    </visual>
    <collision>
      <geometry>
        <box size="1 0.8 0.05"/>
      </geometry>
     <origin xyz="0 0 ${up_z}" rpy="0 0 0"/>
    </collision>
    <xacro:default_inertial mass="50"/>
  </link>



  <link name="left_front_wheel">
    <visual>
      <geometry>
        <cylinder length="0.1" radius="0.15"/>
      </geometry>
      <origin xyz="0 0 0" rpy="1.57 0 0"/>
      <material name="black"/>
    </visual>
    <collision>
      <geometry>
        <cylinder length="0.1" radius="0.15"/>
      </geometry>
      <origin xyz="0 0 0" rpy="1.57 0 0"/>
    </collision>
    <xacro:default_inertial mass="1"/>
  </link>


<link name="right_front_wheel">
    <visual>
      <geometry>
        <cylinder length="0.1" radius="0.15"/>
      </geometry>
      <origin xyz="0 0 0" rpy="1.57 0 0"/>
      <material name="black"/>
    </visual>
    <collision>
      <geometry>
        <cylinder length="0.1" radius="0.15"/>
      </geometry>
      <origin xyz="0 0 0" rpy="1.57 0 0"/>
    </collision>
    <xacro:default_inertial mass="1"/>
  </link>

<link name="front_wheel">
    <visual>
      <geometry>
        <cylinder length="0.1" radius="0.15"/>
      </geometry>
      <origin xyz="0 0 0" rpy="1.57 0 0"/>
      <material name="black"/>
    </visual>
    <collision>
      <geometry>
        <cylinder length="0.1" radius="0.15"/>
      </geometry>
      <origin xyz="0 0 0" rpy="1.57 0 0"/>
    </collision>
    <xacro:default_inertial mass="0.01"/>
  </link>

<link name="rear_wheel">
    <visual>
      <geometry>
        <cylinder length="0.1" radius="0.15"/>
      </geometry>
      <origin xyz="0 0 0" rpy="1.57 0 0"/>
      <material name="black"/>
    </visual>
    <collision>
      <geometry>
        <cylinder length="0.1" radius="0.15"/>
      </geometry>
      <origin xyz="0 0 0" rpy="1.57 0 0"/>
    </collision>
    <xacro:default_inertial mass="0.01"/>
  </link>

  <!-- published int launch file -->
  <!-- if published in here the tf time will too fast than other link ,it will display error in rviz-->
  <!--joint name="base_footprint_to_base_link" type="fixed">
    <parent link="base_footprint"/>
    <child link="base_link"/>
    <origin xyz="0 0 0.5" rpy="0 0 0"/>
    <axis xyz="0 1 0"/>
  </joint-->

  <joint name="left_front_wheel_joint" type="continuous">
    <parent link="base_link"/>
    <child link="left_front_wheel"/>
    <origin xyz="-0.0 0.3 ${up_z-0.2}" rpy="0 0 0"/>
    <axis xyz="0 1 0"/>
  </joint>

  <joint name="right_front_wheel_joint" type="continuous">
    <parent link="base_link"/>
    <child link="right_front_wheel"/>
    <origin xyz="-0.0 -0.3 ${up_z-0.2}" rpy="0 0 0" />
    <axis xyz="0 1 0"/>
  </joint>

 
  <joint name="front_wheel_joint" type="continuous">
    <parent link="base_link"/>
    <child link="front_wheel"/>
    <origin xyz="1 0 ${up_z-0.2}" rpy="0 0 0" />
    <axis xyz="0 1 0"/>
  </joint>

 
  <joint name="rear_wheel_joint" type="continuous">
    <parent link="base_link"/>
    <child link="rear_wheel"/>
    <origin xyz="-1 0 ${up_z-0.2}" rpy="0 0 0" />
    <axis xyz="0 1 0"/>
  </joint>

  <xacro:include filename="$(find dhc_houdar_pkg)/urdf/hokuyolaser.xacro" />
  <xacro:hokuyolaser parent_link="base_link">
    <origin xyz="1.0 0 ${up_z+0.4}" rpy="0 0 0" />
  </xacro:hokuyolaser>

<transmission name="left_front_wheel_trans">
  <type>transmission_interface/SimpleTransmission</type>
  <actuator name="$left_front_wheel_motor">
    <mechanicalReduction>1</mechanicalReduction>
  </actuator>
  <joint name="left_front_wheel_joint">
   <hardwareInterface>VelocityJointInterface</hardwareInterface>
  </joint>
</transmission>

<transmission name="right_front_wheel_trans">
  <type>transmission_interface/SimpleTransmission</type>
  <actuator name="$right_front_wheel_motor">
    <mechanicalReduction>1</mechanicalReduction>
  </actuator>
  <joint name="right_front_wheel_joint">
   <hardwareInterface>VelocityJointInterface</hardwareInterface>
  </joint>
</transmission>

<transmission name="front_wheel_trans">
  <type>transmission_interface/SimpleTransmission</type>
  <actuator name="$front_wheel_motor">
    <mechanicalReduction>1</mechanicalReduction>
  </actuator>
  <joint name="front_wheel_joint">
   <hardwareInterface>VelocityJointInterface</hardwareInterface>
  </joint>
</transmission>

<transmission name="rear_wheel_trans">
  <type>transmission_interface/SimpleTransmission</type>
  <actuator name="$rear_wheel_motor">
    <mechanicalReduction>1</mechanicalReduction>
  </actuator>
  <joint name="rear_wheel_joint">
   <hardwareInterface>VelocityJointInterface</hardwareInterface>
  </joint>
</transmission>
<!--transmission name="front_wheel_trans">
  <type>transmission_interface/SimpleTransmission</type>
  <actuator name="$front_wheel_motor">
    <mechanicalReduction>1</mechanicalReduction>
  </actuator>
  <joint name="front_wheel_joint">
   <hardwareInterface>PositionJointInterface</hardwareInterface>
  </joint>
</transmission-->



 <gazebo>
  <plugin name="gazebo_ros_control" filename="libgazebo_ros_control.so">
  <robotNamespace>/</robotNamespace>
  </plugin>
</gazebo>


</robot>
